Workbook

Sheet Usa Purchase
A1: Date | C1: 46082 | D1: AR-26
A2: Party Name | C2: 887544756260 Owais HT
D3: Entry Done
A4: SNo. | B4: Item Name | C4: Color | D4: Storage | E4: IMEI/Serial | F4: Comments | I4: Price USD | J4: Price AED
A5: 1 | B5: iPhone 17 Pro Max | C5: Cosmic Orange | D5: 256 GB | E5: 358051322533887 | I5: 880 | J5: =I5*3.595 -> 3163.6
A6: 2 | B6: iPhone 17 Pro Max | C6: Cosmic Orange | D6: 256 GB | E6: 353837419391642 | I6: 880 | J6: =I6*3.595 -> 3163.6
A7: 3 | B7: iPhone 17 Pro Max | C7: Cosmic Orange | D7: 256 GB | E7: 358051321265978 | F7: Active | I7: 880 | J7: =I7*3.595 -> 3163.6
A8: 4 | B8: iPhone 17 Pro Max | C8: Cosmic Orange | D8: 256 GB | E8: 356605225057831 | F8: Active | I8: 880 | J8: =I8*3.595 -> 3163.6
A9: 5 | B9: iPhone 17 Pro Max | C9: Cosmic Orange | D9: 256 GB | E9: 350889862536879 | I9: 880 | J9: =I9*3.595 -> 3163.6
A10: 6 | B10: iPhone 17 Pro Max | C10: Cosmic Orange | D10: 256 GB | E10: 353263425144000 | I10: 880 | J10: =I10*3.595 -> 3163.6
A11: 7 | B11: iPhone 17 Pro Max | C11: Cosmic Orange | D11: 256 GB | E11: 359614544687390 | I11: 880 | J11: =I11*3.595 -> 3163.6
A12: 8 | B12: iPhone 17 Pro Max | C12: Silver | D12: 256 GB | E12: 359912587219711 | I12: 900 | J12: =I12*3.595 -> 3235.5
A13: 9 | B13: iPhone 17 Pro Max | C13: Silver | D13: 256 GB | E13: 359614541610171 | I13: 900 | J13: =I13*3.595 -> 3235.5
A14: 10 | B14: iPhone 17 Pro Max | C14: Silver | D14: 256 GB | E14: 359614540060931 | I14: 900 | J14: =I14*3.595 -> 3235.5
A15: 11 | B15: iPhone 17 Pro Max | C15: Silver | D15: 512 GB | E15: 353263423932034 | I15: 980 | J15: =I15*3.595 -> 3523.1
A16: 12 | B16: iPhone 16 Pro Max | C16: Desert Ti | D16: 256 GB | E16: 355008282401839 | I16: 730 | J16: =I16*3.595 -> 2624.35
A17: 13 | B17: iPhone 16 Pro Max (FU Kit) | C17: White Ti | D17: 1 TB | E17: 355445520481381 | F17: Active Factory Unlock | I17: 620 | J17: =I17*3.595 -> 2228.9
A18: 14 | B18: iPhone 16 Pro (FU Kit) | C18: Black Ti | D18: 256 GB | E18: 357719281961635 | F18: Active Factory Unlock | I18: 620 | J18: =I18*3.595 -> 2228.9
A19: 15 | B19: iPhone 16 (FU Kit) | C19: Ultramarine | D19: 256 GB | E19: 357762265949689 | F19: Active Factory Unlock | I19: 470 | J19: =I19*3.595 -> 1689.65
A20: 16 | B20: iPhone 16 (FU Kit) | C20: Teal | D20: 128 GB | E20: 353685834007800 | F20: Active Factory Unlock | I20: 350 | J20: =I20*3.595 -> 1258.25
A21: 17 | B21: iPhone 16 | C21: White | D21: 256 GB | E21: 357985605788059 | I21: 470 | J21: =I21*3.595 -> 1689.65
A22: 18 | B22: iPhone 16e | C22: Black | D22: 128 GB | E22: 355852812209224 | F22: MDM | I22: 165 | J22: =I22*3.595 -> 593.175
A23: 19 | B23: iPhone 16e | C23: Black | D23: 128 GB | E23: 350138782777415 | I23: 205 | J23: =I23*3.595 -> 736.975
A24: 20 | B24: iPhone 16e | C24: White | D24: 128 GB | E24: 352515983937724 | F24: T-Mobile | I24: 205 | J24: =I24*3.595 -> 736.975
A25: 21 | B25: iPhone 16e | C25: White | D25: 128 GB | E25: 350304975570948 | I25: 205 | J25: =I25*3.595 -> 736.975
A26: 22 | B26: iPhone 15 | C26: Blue | D26: 128 GB | E26: 356832826585198 | F26: T-Mobile | I26: 280 | J26: =I26*3.595 -> 1006.6
A27: 23 | B27: iPhone 14 Pro Max (FU Kit) | C27: Deep Purple | D27: 128 GB | E27: 357773240293275 | F27: Active Factory Unlock | I27: 410 | J27: =I27*3.595 -> 1473.95
A28: 24 | B28: iPhone 14 Pro Max (FU Kit) | C28: Deep Purple | D28: 256 GB | E28: 357773241392274 | F28: Active Factory Unlock | I28: 420 | J28: =I28*3.595 -> 1509.9
A29: 21 | B29: iPhone 13 (FU Kit) | C29: Product Red | D29: 128 GB | E29: 358691739992588 | F29: Active Factory Unlock | I29: 200 | J29: =I29*3.595 -> 719
A30: 22 | B30: iPhone 11 Pro Max (FU Kit) | C30: Space Gray | D30: 256 GB | E30: 353894107001488 | F30: Active Factory Unlock | I30: 175 | J30: =I30*3.595 -> 629.125
A31: 23 | B31: iPhone SE | C31: Midnight | D31: 128 GB | E31: 358229303109360 | F31: Active | I31: 80 | J31: =I31*3.595 -> 287.6
A32: 24 | B32: iPad Pro M5 11" (W+C) | C32: Space Black | D32: 256 GB | E32: 358112930542452 | F32: Locked | I32: 850 | J32: =I32*3.595 -> 3055.75
A33: 25 | B33: iPad Pro M4 13" (W+C) | C33: Space Black | D33: 256 GB | E33: 356334540274274 | I33: 945 | J33: =I33*3.595 -> 3397.275
A34: 26 | B34: iPad Air M3 13" (W) | C34: Space Gray | D34: 128 GB | E34: SJ56LKQX91F | I34: 550 | J34: =I34*3.595 -> 1977.25
A35: 27 | B35: iPad Air M3 13" (W) | C35: Space Gray | D35: 128 GB | E35: SLJ2DW1GJPG | I35: 600 | J35: =I35*3.595 -> 2157
A36: 28 | B36: iPad A16 (W+C) | C36: Silver | D36: 128 GB | E36: 350094261697964 | I36: 285 | J36: =I36*3.595 -> 1024.575
A37: 29 | B37: iPad A16 (W+C) | C37: Silver | D37: 128 GB | E37: 350094261355704 | I37: 285 | J37: =I37*3.595 -> 1024.575
A38: 30 | B38: iPad Mini A17 Pro (W+C) | C38: Space Gray | D38: 128 GB | E38: 357153132623899 | I38: 430 | J38: =I38*3.595 -> 1545.85
A39: 31 | B39: iPad Mini A17 Pro (W) | C39: Purple | D39: 256 GB | E39: SM04W37XK2M | I39: 475 | J39: =I39*3.595 -> 1707.625
A40: 32 | B40: MacBook Pro M5 14" MDE14LL/A | C40: Space Black | D40: 16 GB, 1 TB | E40: SMT79VX36C5 | I40: 1550 | J40: =I40*3.595 -> 5572.25
...

Sheet Purchases
A3: 1 | B3: NewZeland
B4: Date | C4: Product Name | D4: Qty | E4: Per/Unit (AUD) | F4: Price (AUD) | G4: C. Rate | H4: Per/Unit (AED) | I4: Total Price (AED)
B5: 45672 | C5: Starlink v4 19Units @580 WB | D5: 19 | E5: 580 | F5: =E5*D5 -> 11020 | G5: 2.19 | H5: =E5*G5 -> 1270.2 | I5: =H5*D5 -> 24133.8 | J5: =J4+I5 -> 24133.8
H6: =E6*G6 -> 0 | I6: =H6*D6 -> 0 | J6: =J5+I6 -> 24133.8
H7: =E7*G7 -> 0 | I7: =H7*D7 -> 0 | J7: =J6+I7 -> 24133.8
H8: =E8*G8 -> 0 | I8: =H8*D8 -> 0 | J8: =J7+I8 -> 24133.8
H9: =E9*G9 -> 0 | I9: =H9*D9 -> 0 | J9: =J8+I9 -> 24133.8
H10: =E10*G10 -> 0 | I10: =H10*D10 -> 0 | J10: =J9+I10 -> 24133.8
H11: =E11*G11 -> 0 | I11: =H11*D11 -> 0 | J11: =J10+I11 -> 24133.8
H12: =E12*G12 -> 0 | I12: =H12*D12 -> 0 | J12: =J11+I12 -> 24133.8
H13: =E13*G13 -> 0 | I13: =H13*D13 -> 0 | J13: =J12+I13 -> 24133.8
A16: 2 | B16: NewZeland
B17: Date | C17: Product Name | D17: Qty | E17: Per/Unit (AUD) | F17: Price (AUD) | G17: C. Rate | H17: Per/Unit (AED) | I17: Total Price (AED) | K17: Paid
B18: 45695 | C18: Starlink Mini 500 Units $630 WB | D18: 500 | E18: 630 | F18: =E18*D18 -> 315000 | G18: 2.19 | H18: =E18*G18 -> 1379.7 | I18: =H18*D18 -> 689850 | J18: =J17+I18 -> 689850 | K18: 270000 | L18: =315000-270000 -> 45000 | N18: NewZeland
B19: 45695 | C19: JBL Charge 5 150Units $148 WB | D19: 150 | E19: 148 | F19: =E19*D19 -> 22200 | G19: 2.19 | H19: =E19*G19 -> 324.12 | I19: =H19*D19 -> 48618 | J19: =J18+I19 -> 738468 | N19: Date | O19: Product Name | P19: Qty | Q19: Per/Unit (AUD) | R19: Price (AUD) | S19: C. Rate | T19: Per/Unit (AED) | U19: Total Price (AED)
B20: 45695 | C20: JBL Charge 5 50Units $145 WB | D20: 50 | E20: 145 | F20: =E20*D20 -> 7250 | G20: 2.19 | H20: =E20*G20 -> 317.55 | I20: =H20*D20 -> 15877.5 | J20: =J19+I20 -> 754345.5 | R20: =Q20*P20 -> 0 | T20: =Q20*S20 -> 0 | U20: =T20*P20 -> 0 | V20: =V19+U20 -> 0
B21: 45695 | C21: Google Chrome Cast 250Units $149 WB | D21: 250 | E21: 149 | F21: =E21*D21 -> 37250 | G21: 2.19 | H21: =E21*G21 -> 326.31 | I21: =H21*D21 -> 81577.5 | J21: =J20+I21 -> 835923 | R21: =Q21*P21 -> 0 | T21: =Q21*S21 -> 0 | U21: =T21*P21 -> 0 | V21: =V20+U21 -> 0
F22: =E22*D22 -> 0 | H22: =E22*G22 -> 0 | I22: =H22*D22 -> 0 | J22: =J21+I22 -> 835923 | R22: =Q22*P22 -> 0 | T22: =Q22*S22 -> 0 | U22: =T22*P22 -> 0 | V22: =V21+U22 -> 0
F23: =E23*D23 -> 0 | H23: =E23*G23 -> 0 | I23: =H23*D23 -> 0 | J23: =J22+I23 -> 835923 | R23: =Q23*P23 -> 0 | T23: =Q23*S23 -> 0 | U23: =T23*P23 -> 0 | V23: =V22+U23 -> 0
F24: =E24*D24 -> 0 | H24: =E24*G24 -> 0 | I24: =H24*D24 -> 0 | J24: =J23+I24 -> 835923 | R24: =Q24*P24 -> 0 | T24: =Q24*S24 -> 0 | U24: =T24*P24 -> 0 | V24: =V23+U24 -> 0
F25: =E25*D25 -> 0 | H25: =E25*G25 -> 0 | I25: =H25*D25 -> 0 | J25: =J24+I25 -> 835923 | R25: =Q25*P25 -> 0 | T25: =Q25*S25 -> 0 | U25: =T25*P25 -> 0 | V25: =V24+U25 -> 0
F26: =E26*D26 -> 0 | H26: =E26*G26 -> 0 | I26: =H26*D26 -> 0 | J26: =J25+I26 -> 835923 | R26: =Q26*P26 -> 0 | T26: =Q26*S26 -> 0 | U26: =T26*P26 -> 0 | V26: =V25+U26 -> 0
R27: =Q27*P27 -> 0 | T27: =Q27*S27 -> 0 | U27: =T27*P27 -> 0 | V27: =V26+U27 -> 0
R28: =Q28*P28 -> 0 | T28: =Q28*S28 -> 0 | U28: =T28*P28 -> 0 | V28: =V27+U28 -> 0
A29: 3 | B29: Australia
B30: Date | C30: Product Name | D30: Qty | E30: Per/Unit (AUD) | F30: Price (AUD) | G30: C. Rate | H30: Per/Unit (AED) | I30: Total Price (AED)
B31: 45701 | C31: Instax Wide 400 5units $188 WB | D31: 5 | E31: 188 | F31: =E31*D31 -> 940 | G31: 2.32 | H31: =E31*G31 -> 436.16 | I31: =H31*D31 -> 2180.8 | J31: =J30+I31 -> 2180.8
B32: 45701 | C32: JBL Charge5 125Units $133.30 WB | D32: 125 | E32: 133.3 | F32: =E32*D32 -> 16662.5 | G32: 2.32 | H32: =E32*G32 -> 309.256 | I32: =H32*D32 -> 38657 | J32: =J31+I32 -> 40837.8 | N32: Australia
F33: =E33*D33 -> 0 | H33: =E33*G33 -> 0 | I33: =H33*D33 -> 0 | J33: =J32+I33 -> 40837.8 | N33: Date | O33: Product Name | P33: Store | Q33: Status | R33: Qty | S33: Per/Unit (AUD) | T33: Discount % | U33: Discount | V33: Per/Unit After Dis. | W33: Total AUD | X33: C.Rate | Y33: Per/unit AED | Z33: Total Price (AED)
F34: =E34*D34 -> 0 | H34: =E34*G34 -> 0 | I34: =H34*D34 -> 0 | J34: =J33+I34 -> 40837.8 | U34: =S34*T34% -> 0 | V34: =S34-U34 -> 0 | W34: =R34*V34 -> 0 | X34: 2.33 | Y34: =V34*X34 -> 0 | Z34: =R34*Y34 -> 0 | AA34: =AA33+Z34 -> 0
F35: =E35*D35 -> 0 | H35: =E35*G35 -> 0 | I35: =H35*D35 -> 0 | J35: =J34+I35 -> 40837.8 | U35: =S35*T35% -> 0 | V35: =S35-U35 -> 0 | W35: =R35*V35 -> 0 | Y35: =V35*X35 -> 0 | Z35: =R35*Y35 -> 0 | AA35: =AA34+Z35 -> 0
F36: =E36*D36 -> 0 | H36: =E36*G36 -> 0 | I36: =H36*D36 -> 0 | J36: =J35+I36 -> 40837.8 | U36: =S36*T36% -> 0 | V36: =S36-U36 -> 0 | W36: =R36*V36 -> 0 | Y36: =V36*X36 -> 0 | Z36: =R36*Y36 -> 0 | AA36: =AA35+Z36 -> 0
F37: =E37*D37 -> 0 | H37: =E37*G37 -> 0 | I37: =H37*D37 -> 0 | J37: =J36+I37 -> 40837.8 | U37: =S37*T37% -> 0 | V37: =S37-U37 -> 0 | W37: =R37*V37 -> 0 | Y37: =V37*X37 -> 0 | Z37: =R37*Y37 -> 0 | AA37: =AA36+Z37 -> 0
F38: =E38*D38 -> 0 | H38: =E38*G38 -> 0 | I38: =H38*D38 -> 0 | J38: =J37+I38 -> 40837.8 | U38: =S38*T38% -> 0 | V38: =S38-U38 -> 0 | W38: =R38*V38 -> 0 | Y38: =V38*X38 -> 0 | Z38: =R38*Y38 -> 0 | AA38: =AA37+Z38 -> 0
F39: =E39*D39 -> 0 | H39: =E39*G39 -> 0 | I39: =H39*D39 -> 0 | J39: =J38+I39 -> 40837.8 | U39: =S39*T39% -> 0 | V39: =S39-U39 -> 0 | W39: =R39*V39 -> 0 | Y39: =V39*X39 -> 0 | Z39: =R39*Y39 -> 0 | AA39: =AA38+Z39 -> 0
U40: =S40*T40% -> 0 | V40: =S40-U40 -> 0 | W40: =R40*V40 -> 0 | Y40: =V40*X40 -> 0 | Z40: =R40*Y40 -> 0 | AA40: =AA39+Z40 -> 0
U41: =S41*T41% -> 0 | V41: =S41-U41 -> 0 | W41: =R41*V41 -> 0 | Y41: =V41*X41 -> 0 | Z41: =R41*Y41 -> 0 | AA41: =AA40+Z41 -> 0
A42: 4 | B42: NewZeland | U42: =S42*T42% -> 0 | V42: =S42-U42 -> 0 | W42: =R42*V42 -> 0 | Y42: =V42*X42 -> 0 | Z42: =R42*Y42 -> 0 | AA42: =AA41+Z42 -> 0
B43: Date | C43: Product Name | D43: Qty | E43: Per/Unit (AUD) | F43: Price (AUD) | G43: C. Rate | H43: Per/Unit (AED) | I43: Total Price (AED) | U43: =S43*T43% -> 0 | V43: =S43-U43 -> 0 | W43: =R43*V43 -> 0 | Y43: =V43*X43 -> 0 | Z43: =R43*Y43 -> 0 | AA43: =AA42+Z43 -> 0
B44: 45705 | C44: Google Chrome Cast 250Units $149 WB | D44: 250 | E44: 149 | F44: =E44*D44 -> 37250 | G44: 2.19 | H44: =E44*G44 -> 326.31 | I44: =H44*D44 -> 81577.5 | J44: =J43+I44 -> 81577.5
...

Sheet Stock_Transactions
A1: Date | B1: Product Name | C1: Transaction Type | D1: Quantity | E1: Status
A2: 20/02/2025 | B2: STARLINK V4 | C2: Opening | D2: 220
A3: 20/02/2025 | B3: STARLINK MINI | C3: Opening | D3: 300 | N3: STARLINK V4
A4: 20/02/2025 | B4: STRALINK INSTAX CAMERA | C4: Opening | D4: 0 | F4: sell to waheed bhai | N4: STARLINK MINI
A5: 20/02/2025 | B5: JBL CHARGE 5 | C5: Opening | D5: 205 | F5: 130 purchase cancel | N5: STRALINK INSTAX CAMERA
A6: 20/02/2025 | B6: ESSENTIAL FLIP | C6: Opening | D6: 10 | N6: JBL CHARGE 5
A7: 20/02/2025 | B7: CHROME CAST | C7: Opening | D7: 309 | N7: ESSENTIAL FLIP
A8: 20/02/2025 | B8: PS5 | C8: Opening | D8: 15 | N8: CHROME CAST | O8: DONE
A9: 20/02/2025 | B9: APPLE I MAC | C9: Opening | D9: 7 | N9: PS5 | O9: DONE
A10: 20/02/2025 | B10: MACBOOK M4 | C10: Opening | D10: 4 | N10: APPLE I MAC | O10: DONE
A11: 20/02/2025 | B11: BREVILLE COFFEE MACHINE | C11: Opening | D11: 2 | N11: MACBOOK M4 | O11: DONE
A12: 20/02/2025 | B12: DELONGI COFFEE MACHINE | C12: Opening | D12: 2 | N12: AIRPODS | O12: DONE
A13: 20/02/2025 | B13: DYSON | C13: Opening | D13: 2 | N13: BREVILLE COFFEE MACHINE | O13: DONE
A14: 20/02/2025 | B14: MACBOOK M3 | C14: Opening | D14: 2 | N14: DELONGI COFFEE MACHINE | O14: DONE
A15: 20/02/2025 | B15: STARLINK HIGH.P KIT | C15: Opening | D15: 21 | N15: DYSON | O15: DONE
A16: 20/02/2025 | B16: INSTAX WIDE 400 | C16: Opening | D16: 5 | N16: MACBOOK M3 | O16: DONE
A17: 20/02/2025 | B17: APPLE WATCH ULTRA | C17: Opening | D17: 1 | N17: STARLINK HIGH.P KIT | O17: DONE
A18: 20/02/2025 | B18: PRINTER | C18: Opening | D18: 1 | N18: INSTAX WIDE 400 | O18: DONE
A19: 20/02/2025 | B19: DJI MAVIC PRO 3 DRONE | C19: Opening | D19: 2 | N19: INSTAX MINI EVO | O19: DONE
N20: INSTAX Li PLAY | O20: DONE
N21: INSTAX MINI 40 | O21: DONE
A22: 45709 | B22: MACBOOK M4 | C22: Purchase | D22: 9 | N22: INSTAX MINI 99 | O22: DONE
A23: 45709 | B23: AIRPODS | C23: Purchase | D23: 9 | N23: APPLE WATCH ULTRA | O23: DONE
A24: 45709 | B24: INSTAX WIDE 400 | C24: Purchase | D24: 10 | N24: PRINTER | O24: DONE
A25: 45709 | B25: INSTAX MINI EVO | C25: Purchase | D25: 1 | N25: DJI MAVIC PRO 3 DRONE | O25: DONE
A26: 45709 | B26: INSTAX Li PLAY | C26: Purchase | D26: 1
A27: 45709 | B27: INSTAX MINI 40 | C27: Purchase | D27: 1 | N27: Meta Quest 3 512
A28: 45709 | B28: INSTAX MINI 99 | C28: Purchase | D28: 1 | N28: iPhone16 Pro Max 256
N29: iPad Pro 11 256 Cellular Unlock
A30: 45711 | B30: MACBOOK M4 | C30: Purchase | D30: 13
A31: 45711 | B31: MACBOOK M4 | C31: Purchase | D31: 2 | N31: iPad Pro 11 256 Wifi Only
A32: 45711 | B32: AIRPODS | C32: Purchase | D32: 13 | N32: iPad Air 13 128 Wifi Only
A33: 45711 | B33: AIRPODS | C33: Purchase | D33: 2 | N33: iPad Air 13 256 Wifi Only
A34: 45711 | B34: APPLE I MAC | C34: Purchase | D34: 1
A35: 45711 | B35: AIRPODS | C35: Purchase (for Imacs) | D35: 3 | N35: iPhone16 Pro 256
N36: iPhone16 Pro 128
N37: Ps5 Controller Dual sense
N38: Beats Fit Pro
N39: Beats Studio Buds
A40: 45713 | B40: PS5 | C40: Sale | D40: -15 | N40: iPhone 15 Pro 256
...

Sheet Product_Master
F1: Australia | H1: NewZeland | I1: Stock in Dubai
A2: S.No | B2: Product Name) | C2: Total Purchased | D2: Total Sold | E2: Total in Stock | F2: (Currently Present) | G2: Pending | H2: Pending | I2: (Currently Present) | J2: In Shipping | K2: Pending in Dubai | N2: Currently in shipping
A3: 1 | B3: STARLINK V4 | C3: =SUMIFS(Stock_Transactions!D:D, Stock_Transactions!B:B, B3, Stock_Transactions!D:D, ">0") -> 6023 | D3: =SUMIFS(Stock_Transactions!D:D, Stock_Transactions!B:B, B3, Stock_Transactions!D:D, "<0") * -1 -> 6076 | E3: =C3-D3 -> -53 | F3: =E3-G3-H3-I3-J3 -> -58 | G3: =SUMIF(Pending_Stock!C:C, B3, Pending_Stock!F:F) -> 0 | H3: =SUMIF(Pending_Stock!I:I, B3, Pending_Stock!L:L) -> 0 | I3: =SUMIF(ShipToDubai!C:C, B3, ShipToDubai!F:F) - (SUMIFS(Stock_Transactions!D:D, Stock_Transactions!B:B, B3, Stock_Transactions!D:D, "<0") * -1) -> 5 | J3: =SUMIF(ShipToDubai!C:C, B3, ShipToDubai!G:G) -> 0 | L3: 2 problem | N3: "=SUMIF(ShipToDubai!C:C, A3, ShipToDubai!G:G)"
A4: =A3+1 -> 2 | B4: STARLINK MINI | C4: =SUMIFS(Stock_Transactions!D:D, Stock_Transactions!B:B, B4, Stock_Transactions!D:D, ">0") -> 1204 | D4: =SUMIFS(Stock_Transactions!D:D, Stock_Transactions!B:B, B4, Stock_Transactions!D:D, "<0") * -1 -> 1203 | E4: =C4-D4 -> 1 | F4: =E4-G4-H4-I4-J4 -> 0 | G4: =SUMIF(Pending_Stock!C:C, B4, Pending_Stock!F:F) -> 0 | H4: =SUMIF(Pending_Stock!I:I, B4, Pending_Stock!L:L) -> 0 | I4: =SUMIF(ShipToDubai!C:C, B4, ShipToDubai!F:F) - (SUMIFS(Stock_Transactions!D:D, Stock_Transactions!B:B, B4, Stock_Transactions!D:D, "<0") * -1) -> 1 | J4: =SUMIF(ShipToDubai!C:C, B4, ShipToDubai!G:G) -> 0 | L4: 30ok
A5: =A4+1 -> 3 | B5: AIRPODS | C5: =SUMIFS(Stock_Transactions!D:D, Stock_Transactions!B:B, B5, Stock_Transactions!D:D, ">0") -> 138 | D5: =SUMIFS(Stock_Transactions!D:D, Stock_Transactions!B:B, B5, Stock_Transactions!D:D, "<0") * -1 -> 138 | E5: =C5-D5 -> 0 | F5: =E5-G5-H5-I5-J5 -> 0 | G5: =SUMIF(Pending_Stock!C:C, B5, Pending_Stock!F:F) -> 0 | H5: =SUMIF(Pending_Stock!I:I, B5, Pending_Stock!L:L) -> 0 | I5: =SUMIF(ShipToDubai!C:C, B5, ShipToDubai!F:F) - (SUMIFS(Stock_Transactions!D:D, Stock_Transactions!B:B, B5, Stock_Transactions!D:D, "<0") * -1) -> 0 | J5: =SUMIF(ShipToDubai!C:C, B5, ShipToDubai!G:G) -> 0 | N5: Pending in Newzelnd
A6: =A5+1 -> 4 | B6: JBL CHARGE 5 | C6: =SUMIFS(Stock_Transactions!D:D, Stock_Transactions!B:B, B6, Stock_Transactions!D:D, ">0") -> 205 | D6: =SUMIFS(Stock_Transactions!D:D, Stock_Transactions!B:B, B6, Stock_Transactions!D:D, "<0") * -1 -> 205 | E6: =C6-D6 -> 0 | F6: =E6-G6-H6-I6-J6 -> 0 | G6: =SUMIF(Pending_Stock!C:C, B6, Pending_Stock!F:F) -> 0 | H6: =SUMIF(Pending_Stock!I:I, B6, Pending_Stock!L:L) -> 0 | I6: =SUMIF(ShipToDubai!C:C, B6, ShipToDubai!F:F) - (SUMIFS(Stock_Transactions!D:D, Stock_Transactions!B:B, B6, Stock_Transactions!D:D, "<0") * -1) -> 0 | J6: =SUMIF(ShipToDubai!C:C, B6, ShipToDubai!G:G) -> 0 | N6: "=SUMIF(Pending_Stock!I:I, A3, Pending_Stock!L:L)"
A7: =A6+1 -> 5 | B7: ESSENTIAL FLIP | C7: =SUMIFS(Stock_Transactions!D:D, Stock_Transactions!B:B, B7, Stock_Transactions!D:D, ">0") -> 10 | D7: =SUMIFS(Stock_Transactions!D:D, Stock_Transactions!B:B, B7, Stock_Transactions!D:D, "<0") * -1 -> 10 | E7: =C7-D7 -> 0 | F7: =E7-G7-H7-I7-J7 -> 0 | G7: =SUMIF(Pending_Stock!C:C, B7, Pending_Stock!F:F) -> 0 | H7: =SUMIF(Pending_Stock!I:I, B7, Pending_Stock!L:L) -> 0 | I7: =SUMIF(ShipToDubai!C:C, B7, ShipToDubai!F:F) - (SUMIFS(Stock_Transactions!D:D, Stock_Transactions!B:B, B7, Stock_Transactions!D:D, "<0") * -1) -> 0 | J7: =SUMIF(ShipToDubai!C:C, B7, ShipToDubai!G:G) -> 0 | L7: ok
A8: =A7+1 -> 6 | B8: CHROME CAST | C8: =SUMIFS(Stock_Transactions!D:D, Stock_Transactions!B:B, B8, Stock_Transactions!D:D, ">0") -> 559 | D8: =SUMIFS(Stock_Transactions!D:D, Stock_Transactions!B:B, B8, Stock_Transactions!D:D, "<0") * -1 -> 559 | E8: =C8-D8 -> 0 | F8: =E8-G8-H8-I8-J8 -> 0 | G8: =SUMIF(Pending_Stock!C:C, B8, Pending_Stock!F:F) -> 0 | H8: =SUMIF(Pending_Stock!I:I, B8, Pending_Stock!L:L) -> 0 | I8: =SUMIF(ShipToDubai!C:C, B8, ShipToDubai!F:F) - (SUMIFS(Stock_Transactions!D:D, Stock_Transactions!B:B, B8, Stock_Transactions!D:D, "<0") * -1) -> 0 | J8: =SUMIF(ShipToDubai!C:C, B8, ShipToDubai!G:G) -> 0 | L8: ok | N8: Pending in Australia
A9: =A8+1 -> 7 | B9: PS5 | C9: =SUMIFS(Stock_Transactions!D:D, Stock_Transactions!B:B, B9, Stock_Transactions!D:D, ">0") -> 438 | D9: =SUMIFS(Stock_Transactions!D:D, Stock_Transactions!B:B, B9, Stock_Transactions!D:D, "<0") * -1 -> 437 | E9: =C9-D9 -> 1 | F9: =E9-G9-H9-I9-J9 -> 1 | G9: =SUMIF(Pending_Stock!C:C, B9, Pending_Stock!F:F) -> 0 | H9: =SUMIF(Pending_Stock!I:I, B9, Pending_Stock!L:L) -> 0 | I9: =SUMIF(ShipToDubai!C:C, B9, ShipToDubai!F:F) - (SUMIFS(Stock_Transactions!D:D, Stock_Transactions!B:B, B9, Stock_Transactions!D:D, "<0") * -1) -> 0 | J9: =SUMIF(ShipToDubai!C:C, B9, ShipToDubai!G:G) -> 0 | N9: "=SUMIF(Pending_Stock!C:C, A3, Pending_Stock!F:F)"
A10: =A9+1 -> 8 | B10: APPLE I MAC | C10: =SUMIFS(Stock_Transactions!D:D, Stock_Transactions!B:B, B10, Stock_Transactions!D:D, ">0") -> 11 | D10: =SUMIFS(Stock_Transactions!D:D, Stock_Transactions!B:B, B10, Stock_Transactions!D:D, "<0") * -1 -> 10 | E10: =C10-D10 -> 1 | F10: =E10-G10-H10-I10-J10 -> 0 | G10: =SUMIF(Pending_Stock!C:C, B10, Pending_Stock!F:F) -> 0 | H10: =SUMIF(Pending_Stock!I:I, B10, Pending_Stock!L:L) -> 0 | I10: =SUMIF(ShipToDubai!C:C, B10, ShipToDubai!F:F) - (SUMIFS(Stock_Transactions!D:D, Stock_Transactions!B:B, B10, Stock_Transactions!D:D, "<0") * -1) -> 1 | J10: =SUMIF(ShipToDubai!C:C, B10, ShipToDubai!G:G) -> 0
A11: =A10+1 -> 9 | B11: MACBOOK M4 | C11: =SUMIFS(Stock_Transactions!D:D, Stock_Transactions!B:B, B11, Stock_Transactions!D:D, ">0") -> 92 | D11: =SUMIFS(Stock_Transactions!D:D, Stock_Transactions!B:B, B11, Stock_Transactions!D:D, "<0") * -1 -> 92 | E11: =C11-D11 -> 0 | F11: =E11-G11-H11-I11-J11 -> 0 | G11: =SUMIF(Pending_Stock!C:C, B11, Pending_Stock!F:F) -> 0 | H11: =SUMIF(Pending_Stock!I:I, B11, Pending_Stock!L:L) -> 0 | I11: =SUMIF(ShipToDubai!C:C, B11, ShipToDubai!F:F) - (SUMIFS(Stock_Transactions!D:D, Stock_Transactions!B:B, B11, Stock_Transactions!D:D, "<0") * -1) -> 0 | J11: =SUMIF(ShipToDubai!C:C, B11, ShipToDubai!G:G) -> 0
A12: =A11+1 -> 10 | B12: Macbook Pro 16/512 | C12: =SUMIFS(Stock_Transactions!D:D, Stock_Transactions!B:B, B12, Stock_Transactions!D:D, ">0") -> 6 | D12: =SUMIFS(Stock_Transactions!D:D, Stock_Transactions!B:B, B12, Stock_Transactions!D:D, "<0") * -1 -> 6 | E12: =C12-D12 -> 0 | F12: =E12-G12-H12-I12-J12 -> 0 | G12: =SUMIF(Pending_Stock!C:C, B12, Pending_Stock!F:F) -> 0 | H12: =SUMIF(Pending_Stock!I:I, B12, Pending_Stock!L:L) -> 0 | I12: =SUMIF(ShipToDubai!C:C, B12, ShipToDubai!F:F) - (SUMIFS(Stock_Transactions!D:D, Stock_Transactions!B:B, B12, Stock_Transactions!D:D, "<0") * -1) -> 0 | J12: =SUMIF(ShipToDubai!C:C, B12, ShipToDubai!G:G) -> 0 | N12: Delivered to Dubai
A13: =A12+1 -> 11 | B13: BREVILLE COFFEE MACHINE | C13: =SUMIFS(Stock_Transactions!D:D, Stock_Transactions!B:B, B13, Stock_Transactions!D:D, ">0") -> 2 | D13: =SUMIFS(Stock_Transactions!D:D, Stock_Transactions!B:B, B13, Stock_Transactions!D:D, "<0") * -1 -> 2 | E13: =C13-D13 -> 0 | F13: =E13-G13-H13-I13-J13 -> 0 | G13: =SUMIF(Pending_Stock!C:C, B13, Pending_Stock!F:F) -> 0 | H13: =SUMIF(Pending_Stock!I:I, B13, Pending_Stock!L:L) -> 0 | I13: =SUMIF(ShipToDubai!C:C, B13, ShipToDubai!F:F) - (SUMIFS(Stock_Transactions!D:D, Stock_Transactions!B:B, B13, Stock_Transactions!D:D, "<0") * -1) -> 0 | J13: =SUMIF(ShipToDubai!C:C, B13, ShipToDubai!G:G) -> 0 | N13: "=SUMIF(ShipToDubai!C:C, A3, ShipToDubai!F:F)"
A14: =A13+1 -> 12 | B14: DELONGI COFFEE MACHINE | C14: =SUMIFS(Stock_Transactions!D:D, Stock_Transactions!B:B, B14, Stock_Transactions!D:D, ">0") -> 2 | D14: =SUMIFS(Stock_Transactions!D:D, Stock_Transactions!B:B, B14, Stock_Transactions!D:D, "<0") * -1 -> 2 | E14: =C14-D14 -> 0 | F14: =E14-G14-H14-I14-J14 -> 0 | G14: =SUMIF(Pending_Stock!C:C, B14, Pending_Stock!F:F) -> 0 | H14: =SUMIF(Pending_Stock!I:I, B14, Pending_Stock!L:L) -> 0 | I14: =SUMIF(ShipToDubai!C:C, B14, ShipToDubai!F:F) - (SUMIFS(Stock_Transactions!D:D, Stock_Transactions!B:B, B14, Stock_Transactions!D:D, "<0") * -1) -> 0 | J14: =SUMIF(ShipToDubai!C:C, B14, ShipToDubai!G:G) -> 0
A15: =A14+1 -> 13 | B15: DYSON | C15: =SUMIFS(Stock_Transactions!D:D, Stock_Transactions!B:B, B15, Stock_Transactions!D:D, ">0") -> 2 | D15: =SUMIFS(Stock_Transactions!D:D, Stock_Transactions!B:B, B15, Stock_Transactions!D:D, "<0") * -1 -> 2 | E15: =C15-D15 -> 0 | F15: =E15-G15-H15-I15-J15 -> 0 | G15: =SUMIF(Pending_Stock!C:C, B15, Pending_Stock!F:F) -> 0 | H15: =SUMIF(Pending_Stock!I:I, B15, Pending_Stock!L:L) -> 0 | I15: =SUMIF(ShipToDubai!C:C, B15, ShipToDubai!F:F) - (SUMIFS(Stock_Transactions!D:D, Stock_Transactions!B:B, B15, Stock_Transactions!D:D, "<0") * -1) -> 0 | J15: =SUMIF(ShipToDubai!C:C, B15, ShipToDubai!G:G) -> 0 | L15: ok | N15: Delivered to Dubai minus Sold in Dubai
A16: =A15+1 -> 14 | B16: MACBOOK M3 | C16: =SUMIFS(Stock_Transactions!D:D, Stock_Transactions!B:B, B16, Stock_Transactions!D:D, ">0") -> 2 | D16: =SUMIFS(Stock_Transactions!D:D, Stock_Transactions!B:B, B16, Stock_Transactions!D:D, "<0") * -1 -> 2 | E16: =C16-D16 -> 0 | F16: =E16-G16-H16-I16-J16 -> 0 | G16: =SUMIF(Pending_Stock!C:C, B16, Pending_Stock!F:F) -> 0 | H16: =SUMIF(Pending_Stock!I:I, B16, Pending_Stock!L:L) -> 0 | I16: =SUMIF(ShipToDubai!C:C, B16, ShipToDubai!F:F) - (SUMIFS(Stock_Transactions!D:D, Stock_Transactions!B:B, B16, Stock_Transactions!D:D, "<0") * -1) -> 0 | J16: =SUMIF(ShipToDubai!C:C, B16, ShipToDubai!G:G) -> 0 | L16: ok | N16: "=SUMIF(ShipToDubai!C:C, A3, ShipToDubai!F:F) - (SUMIFS(Stock_Transactions!D:D, Stock_Transactions!B:B, A3, Stock_Transactions!D:D, "<0") * -1)"
A17: =A16+1 -> 15 | B17: STARLINK HIGH.P KIT | C17: =SUMIFS(Stock_Transactions!D:D, Stock_Transactions!B:B, B17, Stock_Transactions!D:D, ">0") -> 23 | D17: =SUMIFS(Stock_Transactions!D:D, Stock_Transactions!B:B, B17, Stock_Transactions!D:D, "<0") * -1 -> 23 | E17: =C17-D17 -> 0 | F17: =E17-G17-H17-I17-J17 -> 0 | G17: =SUMIF(Pending_Stock!C:C, B17, Pending_Stock!F:F) -> 0 | H17: =SUMIF(Pending_Stock!I:I, B17, Pending_Stock!L:L) -> 0 | I17: =SUMIF(ShipToDubai!C:C, B17, ShipToDubai!F:F) - (SUMIFS(Stock_Transactions!D:D, Stock_Transactions!B:B, B17, Stock_Transactions!D:D, "<0") * -1) -> 0 | J17: =SUMIF(ShipToDubai!C:C, B17, ShipToDubai!G:G) -> 0 | L17: ok
A18: =A17+1 -> 16 | B18: INSTAX WIDE 400 | C18: =SUMIFS(Stock_Transactions!D:D, Stock_Transactions!B:B, B18, Stock_Transactions!D:D, ">0") -> 117 | D18: =SUMIFS(Stock_Transactions!D:D, Stock_Transactions!B:B, B18, Stock_Transactions!D:D, "<0") * -1 -> 117 | E18: =C18-D18 -> 0 | F18: =E18-G18-H18-I18-J18 -> 0 | G18: =SUMIF(Pending_Stock!C:C, B18, Pending_Stock!F:F) -> 0 | H18: =SUMIF(Pending_Stock!I:I, B18, Pending_Stock!L:L) -> 0 | I18: =SUMIF(ShipToDubai!C:C, B18, ShipToDubai!F:F) - (SUMIFS(Stock_Transactions!D:D, Stock_Transactions!B:B, B18, Stock_Transactions!D:D, "<0") * -1) -> 0 | J18: =SUMIF(ShipToDubai!C:C, B18, ShipToDubai!G:G) -> 0 | L18: ok
A19: =A18+1 -> 17 | B19: INSTAX MINI EVO | C19: =SUMIFS(Stock_Transactions!D:D, Stock_Transactions!B:B, B19, Stock_Transactions!D:D, ">0") -> 843 | D19: =SUMIFS(Stock_Transactions!D:D, Stock_Transactions!B:B, B19, Stock_Transactions!D:D, "<0") * -1 -> 843 | E19: =C19-D19 -> 0 | F19: =E19-G19-H19-I19-J19 -> 0 | G19: =SUMIF(Pending_Stock!C:C, B19, Pending_Stock!F:F) -> 0 | H19: =SUMIF(Pending_Stock!I:I, B19, Pending_Stock!L:L) -> 0 | I19: =SUMIF(ShipToDubai!C:C, B19, ShipToDubai!F:F) - (SUMIFS(Stock_Transactions!D:D, Stock_Transactions!B:B, B19, Stock_Transactions!D:D, "<0") * -1) -> 0 | J19: =SUMIF(ShipToDubai!C:C, B19, ShipToDubai!G:G) -> 0 | N19: Total purchase quantity of a particular Product
A20: =A19+1 -> 18 | B20: INSTAX MINI 12 | C20: =SUMIFS(Stock_Transactions!D:D, Stock_Transactions!B:B, B20, Stock_Transactions!D:D, ">0") -> 57 | D20: =SUMIFS(Stock_Transactions!D:D, Stock_Transactions!B:B, B20, Stock_Transactions!D:D, "<0") * -1 -> 57 | E20: =C20-D20 -> 0 | F20: =E20-G20-H20-I20-J20 -> 0 | G20: =SUMIF(Pending_Stock!C:C, B20, Pending_Stock!F:F) -> 0 | H20: =SUMIF(Pending_Stock!I:I, B20, Pending_Stock!L:L) -> 0 | I20: =SUMIF(ShipToDubai!C:C, B20, ShipToDubai!F:F) - (SUMIFS(Stock_Transactions!D:D, Stock_Transactions!B:B, B20, Stock_Transactions!D:D, "<0") * -1) -> 0 | J20: =SUMIF(ShipToDubai!C:C, B20, ShipToDubai!G:G) -> 0 | L20: ok | N20: "=SUMIFS(Stock_Transactions!D:D, Stock_Transactions!B:B, A3, Stock_Transactions!D:D, ">0")"
A21: =A20+1 -> 19 | B21: INSTAX MINI 99 BUNDEL | C21: =SUMIFS(Stock_Transactions!D:D, Stock_Transactions!B:B, B21, Stock_Transactions!D:D, ">0") -> 30 | D21: =SUMIFS(Stock_Transactions!D:D, Stock_Transactions!B:B, B21, Stock_Transactions!D:D, "<0") * -1 -> 30 | E21: =C21-D21 -> 0 | F21: =E21-G21-H21-I21-J21 -> 0 | G21: =SUMIF(Pending_Stock!C:C, B21, Pending_Stock!F:F) -> 0 | H21: =SUMIF(Pending_Stock!I:I, B21, Pending_Stock!L:L) -> 0 | I21: =SUMIF(ShipToDubai!C:C, B21, ShipToDubai!F:F) - (SUMIFS(Stock_Transactions!D:D, Stock_Transactions!B:B, B21, Stock_Transactions!D:D, "<0") * -1) -> 0 | J21: =SUMIF(ShipToDubai!C:C, B21, ShipToDubai!G:G) -> 0
A22: =A21+1 -> 20 | B22: INSTAX MINI 99 | C22: =SUMIFS(Stock_Transactions!D:D, Stock_Transactions!B:B, B22, Stock_Transactions!D:D, ">0") -> 3 | D22: =SUMIFS(Stock_Transactions!D:D, Stock_Transactions!B:B, B22, Stock_Transactions!D:D, "<0") * -1 -> 3 | E22: =C22-D22 -> 0 | F22: =E22-G22-H22-I22-J22 -> 0 | G22: =SUMIF(Pending_Stock!C:C, B22, Pending_Stock!F:F) -> 0 | H22: =SUMIF(Pending_Stock!I:I, B22, Pending_Stock!L:L) -> 0 | I22: =SUMIF(ShipToDubai!C:C, B22, ShipToDubai!F:F) - (SUMIFS(Stock_Transactions!D:D, Stock_Transactions!B:B, B22, Stock_Transactions!D:D, "<0") * -1) -> 0 | J22: =SUMIF(ShipToDubai!C:C, B22, ShipToDubai!G:G) -> 0 | N22: Total Sale quantity of a particular Product
A23: =A22+1 -> 21 | B23: APPLE WATCH ULTRA | C23: =SUMIFS(Stock_Transactions!D:D, Stock_Transactions!B:B, B23, Stock_Transactions!D:D, ">0") -> 1 | D23: =SUMIFS(Stock_Transactions!D:D, Stock_Transactions!B:B, B23, Stock_Transactions!D:D, "<0") * -1 -> 1 | E23: =C23-D23 -> 0 | F23: =E23-G23-H23-I23-J23 -> 0 | G23: =SUMIF(Pending_Stock!C:C, B23, Pending_Stock!F:F) -> 0 | H23: =SUMIF(Pending_Stock!I:I, B23, Pending_Stock!L:L) -> 0 | I23: =SUMIF(ShipToDubai!C:C, B23, ShipToDubai!F:F) - (SUMIFS(Stock_Transactions!D:D, Stock_Transactions!B:B, B23, Stock_Transactions!D:D, "<0") * -1) -> 0 | J23: =SUMIF(ShipToDubai!C:C, B23, ShipToDubai!G:G) -> 0 | N23: "=SUMIFS(Stock_Transactions!D:D, Stock_Transactions!B:B, A3, Stock_Transactions!D:D, "<0") * -1"
A24: =A23+1 -> 22 | B24: PRINTER | C24: =SUMIFS(Stock_Transactions!D:D, Stock_Transactions!B:B, B24, Stock_Transactions!D:D, ">0") -> 1 | D24: =SUMIFS(Stock_Transactions!D:D, Stock_Transactions!B:B, B24, Stock_Transactions!D:D, "<0") * -1 -> 1 | E24: =C24-D24 -> 0 | F24: =E24-G24-H24-I24-J24 -> 0 | G24: =SUMIF(Pending_Stock!C:C, B24, Pending_Stock!F:F) -> 0 | H24: =SUMIF(Pending_Stock!I:I, B24, Pending_Stock!L:L) -> 0 | I24: =SUMIF(ShipToDubai!C:C, B24, ShipToDubai!F:F) - (SUMIFS(Stock_Transactions!D:D, Stock_Transactions!B:B, B24, Stock_Transactions!D:D, "<0") * -1) -> 0 | J24: =SUMIF(ShipToDubai!C:C, B24, ShipToDubai!G:G) -> 0 | L24: ok
A25: =A24+1 -> 23 | B25: DJI MAVIC PRO 3 DRONE | C25: =SUMIFS(Stock_Transactions!D:D, Stock_Transactions!B:B, B25, Stock_Transactions!D:D, ">0") -> 2 | D25: =SUMIFS(Stock_Transactions!D:D, Stock_Transactions!B:B, B25, Stock_Transactions!D:D, "<0") * -1 -> 2 | E25: =C25-D25 -> 0 | F25: =E25-G25-H25-I25-J25 -> 0 | G25: =SUMIF(Pending_Stock!C:C, B25, Pending_Stock!F:F) -> 0 | H25: =SUMIF(Pending_Stock!I:I, B25, Pending_Stock!L:L) -> 0 | I25: =SUMIF(ShipToDubai!C:C, B25, ShipToDubai!F:F) - (SUMIFS(Stock_Transactions!D:D, Stock_Transactions!B:B, B25, Stock_Transactions!D:D, "<0") * -1) -> 0 | J25: =SUMIF(ShipToDubai!C:C, B25, ShipToDubai!G:G) -> 0 | N25: Total Quantity of a product(total purchase - total sale)
A26: =A25+1 -> 24 | B26: Meta Quest 3 512 | C26: =SUMIFS(Stock_Transactions!D:D, Stock_Transactions!B:B, B26, Stock_Transactions!D:D, ">0") -> 389 | D26: =SUMIFS(Stock_Transactions!D:D, Stock_Transactions!B:B, B26, Stock_Transactions!D:D, "<0") * -1 -> 388 | E26: =C26-D26 -> 1 | F26: =E26-G26-H26-I26-J26 -> 0 | G26: =SUMIF(Pending_Stock!C:C, B26, Pending_Stock!F:F) -> 0 | H26: =SUMIF(Pending_Stock!I:I, B26, Pending_Stock!L:L) -> 0 | I26: =SUMIF(ShipToDubai!C:C, B26, ShipToDubai!F:F) - (SUMIFS(Stock_Transactions!D:D, Stock_Transactions!B:B, B26, Stock_Transactions!D:D, "<0") * -1) -> 1 | J26: =SUMIF(ShipToDubai!C:C, B26, ShipToDubai!G:G) -> 0
A27: =A26+1 -> 25 | B27: Meta Quest 3s 128 | C27: =SUMIFS(Stock_Transactions!D:D, Stock_Transactions!B:B, B27, Stock_Transactions!D:D, ">0") -> 366 | D27: =SUMIFS(Stock_Transactions!D:D, Stock_Transactions!B:B, B27, Stock_Transactions!D:D, "<0") * -1 -> 366 | E27: =C27-D27 -> 0 | F27: =E27-G27-H27-I27-J27 -> 0 | G27: =SUMIF(Pending_Stock!C:C, B27, Pending_Stock!F:F) -> 0 | H27: =SUMIF(Pending_Stock!I:I, B27, Pending_Stock!L:L) -> 0 | I27: =SUMIF(ShipToDubai!C:C, B27, ShipToDubai!F:F) - (SUMIFS(Stock_Transactions!D:D, Stock_Transactions!B:B, B27, Stock_Transactions!D:D, "<0") * -1) -> 0 | J27: =SUMIF(ShipToDubai!C:C, B27, ShipToDubai!G:G) -> 0
A28: =A27+1 -> 26 | B28: Meta Quest 3s 512 | C28: =SUMIFS(Stock_Transactions!D:D, Stock_Transactions!B:B, B28, Stock_Transactions!D:D, ">0") -> 46 | D28: =SUMIFS(Stock_Transactions!D:D, Stock_Transactions!B:B, B28, Stock_Transactions!D:D, "<0") * -1 -> 46 | E28: =C28-D28 -> 0 | F28: =E28-G28-H28-I28-J28 -> 0 | G28: =SUMIF(Pending_Stock!C:C, B28, Pending_Stock!F:F) -> 0 | H28: =SUMIF(Pending_Stock!I:I, B28, Pending_Stock!L:L) -> 0 | I28: =SUMIF(ShipToDubai!C:C, B28, ShipToDubai!F:F) - (SUMIFS(Stock_Transactions!D:D, Stock_Transactions!B:B, B28, Stock_Transactions!D:D, "<0") * -1) -> 0 | J28: =SUMIF(ShipToDubai!C:C, B28, ShipToDubai!G:G) -> 0
A29: =A28+1 -> 27 | B29: iPad Pro 11 256 Wifi Only | C29: =SUMIFS(Stock_Transactions!D:D, Stock_Transactions!B:B, B29, Stock_Transactions!D:D, ">0") -> 15 | D29: =SUMIFS(Stock_Transactions!D:D, Stock_Transactions!B:B, B29, Stock_Transactions!D:D, "<0") * -1 -> 14 | E29: =C29-D29 -> 1 | F29: =E29-G29-H29-I29-J29 -> 0 | G29: =SUMIF(Pending_Stock!C:C, B29, Pending_Stock!F:F) -> 0 | H29: =SUMIF(Pending_Stock!I:I, B29, Pending_Stock!L:L) -> 0 | I29: =SUMIF(ShipToDubai!C:C, B29, ShipToDubai!F:F) - (SUMIFS(Stock_Transactions!D:D, Stock_Transactions!B:B, B29, Stock_Transactions!D:D, "<0") * -1) -> 1 | J29: =SUMIF(ShipToDubai!C:C, B29, ShipToDubai!G:G) -> 0 | L29: loss
A30: =A29+1 -> 28 | B30: iPad Air 13 128 Wifi Only | C30: =SUMIFS(Stock_Transactions!D:D, Stock_Transactions!B:B, B30, Stock_Transactions!D:D, ">0") -> 3 | D30: =SUMIFS(Stock_Transactions!D:D, Stock_Transactions!B:B, B30, Stock_Transactions!D:D, "<0") * -1 -> 3 | E30: =C30-D30 -> 0 | F30: =E30-G30-H30-I30-J30 -> 0 | G30: =SUMIF(Pending_Stock!C:C, B30, Pending_Stock!F:F) -> 0 | H30: =SUMIF(Pending_Stock!I:I, B30, Pending_Stock!L:L) -> 0 | I30: =SUMIF(ShipToDubai!C:C, B30, ShipToDubai!F:F) - (SUMIFS(Stock_Transactions!D:D, Stock_Transactions!B:B, B30, Stock_Transactions!D:D, "<0") * -1) -> 0 | J30: =SUMIF(ShipToDubai!C:C, B30, ShipToDubai!G:G) -> 0
A31: =A30+1 -> 29 | B31: iPad Air 13 256 Wifi Only | C31: =SUMIFS(Stock_Transactions!D:D, Stock_Transactions!B:B, B31, Stock_Transactions!D:D, ">0") -> 1 | D31: =SUMIFS(Stock_Transactions!D:D, Stock_Transactions!B:B, B31, Stock_Transactions!D:D, "<0") * -1 -> 1 | E31: =C31-D31 -> 0 | F31: =E31-G31-H31-I31-J31 -> 0 | G31: =SUMIF(Pending_Stock!C:C, B31, Pending_Stock!F:F) -> 0 | H31: =SUMIF(Pending_Stock!I:I, B31, Pending_Stock!L:L) -> 0 | I31: =SUMIF(ShipToDubai!C:C, B31, ShipToDubai!F:F) - (SUMIFS(Stock_Transactions!D:D, Stock_Transactions!B:B, B31, Stock_Transactions!D:D, "<0") * -1) -> 0 | J31: =SUMIF(ShipToDubai!C:C, B31, ShipToDubai!G:G) -> 0
A32: =A31+1 -> 30 | C32: =SUMIFS(Stock_Transactions!D:D, Stock_Transactions!B:B, B32, Stock_Transactions!D:D, ">0") -> 0 | D32: =SUMIFS(Stock_Transactions!D:D, Stock_Transactions!B:B, B32, Stock_Transactions!D:D, "<0") * -1 -> 0 | E32: =C32-D32 -> 0 | F32: =E32-G32-H32-I32-J32 -> 0 | G32: =SUMIF(Pending_Stock!C:C, B32, Pending_Stock!F:F) -> 0 | H32: =SUMIF(Pending_Stock!I:I, B32, Pending_Stock!L:L) -> 0 | I32: =SUMIF(ShipToDubai!C:C, B32, ShipToDubai!F:F) - (SUMIFS(Stock_Transactions!D:D, Stock_Transactions!B:B, B32, Stock_Transactions!D:D, "<0") * -1) -> 0 | J32: =SUMIF(ShipToDubai!C:C, B32, ShipToDubai!G:G) -> 0 | M32: iPad Air 13 128 Wifi Only | N32: -1
A33: =A32+1 -> 31 | C33: =SUMIFS(Stock_Transactions!D:D, Stock_Transactions!B:B, B33, Stock_Transactions!D:D, ">0") -> 0 | D33: =SUMIFS(Stock_Transactions!D:D, Stock_Transactions!B:B, B33, Stock_Transactions!D:D, "<0") * -1 -> 0 | E33: =C33-D33 -> 0 | F33: =E33-G33-H33-I33-J33 -> 0 | G33: =SUMIF(Pending_Stock!C:C, B33, Pending_Stock!F:F) -> 0 | H33: =SUMIF(Pending_Stock!I:I, B33, Pending_Stock!L:L) -> 0 | I33: =SUMIF(ShipToDubai!C:C, B33, ShipToDubai!F:F) - (SUMIFS(Stock_Transactions!D:D, Stock_Transactions!B:B, B33, Stock_Transactions!D:D, "<0") * -1) -> 0 | J33: =SUMIF(ShipToDubai!C:C, B33, ShipToDubai!G:G) -> 0 | K33: Pakistan | M33: CANON SX740 | N33: -2
A34: =A33+1 -> 32 | B34: Ps5 Controller Dual sense | C34: =SUMIFS(Stock_Transactions!D:D, Stock_Transactions!B:B, B34, Stock_Transactions!D:D, ">0") -> 170 | D34: =SUMIFS(Stock_Transactions!D:D, Stock_Transactions!B:B, B34, Stock_Transactions!D:D, "<0") * -1 -> 170 | E34: =C34-D34 -> 0 | F34: =E34-G34-H34-I34-J34 -> 0 | G34: =SUMIF(Pending_Stock!C:C, B34, Pending_Stock!F:F) -> 0 | H34: =SUMIF(Pending_Stock!I:I, B34, Pending_Stock!L:L) -> 0 | I34: =SUMIF(ShipToDubai!C:C, B34, ShipToDubai!F:F) - (SUMIFS(Stock_Transactions!D:D, Stock_Transactions!B:B, B34, Stock_Transactions!D:D, "<0") * -1) -> 0 | J34: =SUMIF(ShipToDubai!C:C, B34, ShipToDubai!G:G) -> 0 | L34: ok | M34: Ipad Pro 13" W+C Black 512gb | N34: -1
A35: =A34+1 -> 33 | B35: Beats Fit Pro | C35: =SUMIFS(Stock_Transactions!D:D, Stock_Transactions!B:B, B35, Stock_Transactions!D:D, ">0") -> 17 | D35: =SUMIFS(Stock_Transactions!D:D, Stock_Transactions!B:B, B35, Stock_Transactions!D:D, "<0") * -1 -> 17 | E35: =C35-D35 -> 0 | F35: =E35-G35-H35-I35-J35 -> 0 | G35: =SUMIF(Pending_Stock!C:C, B35, Pending_Stock!F:F) -> 0 | H35: =SUMIF(Pending_Stock!I:I, B35, Pending_Stock!L:L) -> 0 | I35: =SUMIF(ShipToDubai!C:C, B35, ShipToDubai!F:F) - (SUMIFS(Stock_Transactions!D:D, Stock_Transactions!B:B, B35, Stock_Transactions!D:D, "<0") * -1) -> 0 | J35: =SUMIF(ShipToDubai!C:C, B35, ShipToDubai!G:G) -> 0 | M35: Samsung Galaxy S25 plus 256 | N35: -1
A36: =A35+1 -> 34 | B36: Beats Pill Speaker | C36: =SUMIFS(Stock_Transactions!D:D, Stock_Transactions!B:B, B36, Stock_Transactions!D:D, ">0") -> 2 | D36: =SUMIFS(Stock_Transactions!D:D, Stock_Transactions!B:B, B36, Stock_Transactions!D:D, "<0") * -1 -> 0 | E36: =C36-D36 -> 2 | F36: =E36-G36-H36-I36-J36 -> 0 | G36: =SUMIF(Pending_Stock!C:C, B36, Pending_Stock!F:F) -> 0 | H36: =SUMIF(Pending_Stock!I:I, B36, Pending_Stock!L:L) -> 0 | I36: =SUMIF(ShipToDubai!C:C, B36, ShipToDubai!F:F) - (SUMIFS(Stock_Transactions!D:D, Stock_Transactions!B:B, B36, Stock_Transactions!D:D, "<0") * -1) -> 2 | J36: =SUMIF(ShipToDubai!C:C, B36, ShipToDubai!G:G) -> 0 | L36: ok | M36: Iphone 16 PM 1TB | N36: -1
A37: =A36+1 -> 35 | B37: iPhone 15 Pro 256 | C37: =SUMIFS(Stock_Transactions!D:D, Stock_Transactions!B:B, B37, Stock_Transactions!D:D, ">0") -> 1 | D37: =SUMIFS(Stock_Transactions!D:D, Stock_Transactions!B:B, B37, Stock_Transactions!D:D, "<0") * -1 -> 1 | E37: =C37-D37 -> 0 | F37: =E37-G37-H37-I37-J37 -> 0 | G37: =SUMIF(Pending_Stock!C:C, B37, Pending_Stock!F:F) -> 0 | H37: =SUMIF(Pending_Stock!I:I, B37, Pending_Stock!L:L) -> 0 | I37: =SUMIF(ShipToDubai!C:C, B37, ShipToDubai!F:F) - (SUMIFS(Stock_Transactions!D:D, Stock_Transactions!B:B, B37, Stock_Transactions!D:D, "<0") * -1) -> 0 | J37: =SUMIF(ShipToDubai!C:C, B37, ShipToDubai!G:G) -> 0 | M37: Ipad A16 WIFI Only | N37: -1
A38: =A37+1 -> 36 | B38: iPhone 16 128 | C38: =SUMIFS(Stock_Transactions!D:D, Stock_Transactions!B:B, B38, Stock_Transactions!D:D, ">0") -> 49 | D38: =SUMIFS(Stock_Transactions!D:D, Stock_Transactions!B:B, B38, Stock_Transactions!D:D, "<0") * -1 -> 49 | E38: =C38-D38 -> 0 | F38: =E38-G38-H38-I38-J38 -> 0 | G38: =SUMIF(Pending_Stock!C:C, B38, Pending_Stock!F:F) -> 0 | H38: =SUMIF(Pending_Stock!I:I, B38, Pending_Stock!L:L) -> 0 | I38: =SUMIF(ShipToDubai!C:C, B38, ShipToDubai!F:F) - (SUMIFS(Stock_Transactions!D:D, Stock_Transactions!B:B, B38, Stock_Transactions!D:D, "<0") * -1) -> 0 | J38: =SUMIF(ShipToDubai!C:C, B38, ShipToDubai!G:G) -> 0 | M38: Ipad Pro 13'' M4 256gb wifi | N38: -2
A39: =A38+1 -> 37 | B39: iPhone 14 Pro Max 128 | C39: =SUMIFS(Stock_Transactions!D:D, Stock_Transactions!B:B, B39, Stock_Transactions!D:D, ">0") -> 5 | D39: =SUMIFS(Stock_Transactions!D:D, Stock_Transactions!B:B, B39, Stock_Transactions!D:D, "<0") * -1 -> 3 | E39: =C39-D39 -> 2 | F39: =E39-G39-H39-I39-J39 -> 0 | G39: =SUMIF(Pending_Stock!C:C, B39, Pending_Stock!F:F) -> 0 | H39: =SUMIF(Pending_Stock!I:I, B39, Pending_Stock!L:L) -> 0 | I39: =SUMIF(ShipToDubai!C:C, B39, ShipToDubai!F:F) - (SUMIFS(Stock_Transactions!D:D, Stock_Transactions!B:B, B39, Stock_Transactions!D:D, "<0") * -1) -> 2 | J39: =SUMIF(ShipToDubai!C:C, B39, ShipToDubai!G:G) -> 0 | M39: Iphone Air 17 256gb | N39: -4
A40: =A39+1 -> 38 | C40: =SUMIFS(Stock_Transactions!D:D, Stock_Transactions!B:B, B40, Stock_Transactions!D:D, ">0") -> 0 | D40: =SUMIFS(Stock_Transactions!D:D, Stock_Transactions!B:B, B40, Stock_Transactions!D:D, "<0") * -1 -> 0 | E40: =C40-D40 -> 0 | F40: =E40-G40-H40-I40-J40 -> 0 | G40: =SUMIF(Pending_Stock!C:C, B40, Pending_Stock!F:F) -> 0 | H40: =SUMIF(Pending_Stock!I:I, B40, Pending_Stock!L:L) -> 0 | I40: =SUMIF(ShipToDubai!C:C, B40, ShipToDubai!F:F) - (SUMIFS(Stock_Transactions!D:D, Stock_Transactions!B:B, B40, Stock_Transactions!D:D, "<0") * -1) -> 0 | J40: =SUMIF(ShipToDubai!C:C, B40, ShipToDubai!G:G) -> 0 | M40: Ipad Air 11'' M3 256gb | N40: -1
...

Sheet GST
G2: GST
B3: from month to month | I3: from month to month
B4: Australia | I4: Newzeland
B5: Date | C5: Product Name | D5: Qty | E5: Per/Unit (AUD) | F5: Total (AUD) | G5: GST | I5: Date | J5: Product Name | K5: Qty | L5: Per/Unit | M5: Total | N5: GST
B6: 45701 | C6: Instax Wide 400 5units $188 WB | D6: 5 | E6: 188 | F6: =E6*D6 -> 940 | G6: =F6/11 -> 85.454545 | I6: 45672 | J6: Starlink v4 19Units @580 WB | K6: 19 | L6: 580 | M6: =L6*K6 -> 11020 | N6: =M6*13.04/100 -> 1437.008
B7: 45701 | C7: JBL Charge5 125Units $133.30 WB | D7: 125 | E7: 133.3 | F7: =E7*D7 -> 16662.5 | G7: =F7/11 -> 1514.7727 | M7: =L7*K7 -> 0 | N7: =M7*13.04/100 -> 0
F8: =E8*D8 -> 0 | G8: =F8/11 -> 0 | I8: 45695 | J8: Starlink Mini 500 Units $630 WB | K8: 500 | L8: 630 | M8: =L8*K8 -> 315000 | N8: =M8*13.04/100 -> 41076
F9: =E9*D9 -> 0 | G9: =F9/11 -> 0 | I9: 45695 | J9: JBL Charge 5 150Units $148 WB | K9: 150 | L9: 148 | M9: =L9*K9 -> 22200 | N9: =M9*13.04/100 -> 2894.88
B10: 45709 | C10: IMAC 1 unit $1919 WB Card | D10: 1 | E10: 1919 | F10: =E10*D10 -> 1919 | G10: =F10/11 -> 174.45455 | I10: 45695 | J10: JBL Charge 5 50Units $145 WB | K10: 50 | L10: 145 | M10: =L10*K10 -> 7250 | N10: =M10*13.04/100 -> 945.4
B11: 45709 | C11: IMAC 1 unit $1934 WB Card | D11: 1 | E11: 1934 | F11: =E11*D11 -> 1934 | G11: =F11/11 -> 175.81818 | I11: 45695 | J11: Google Chrome Cast 250Units $149 WB | K11: 250 | L11: 149 | M11: =L11*K11 -> 37250 | N11: =M11*13.04/100 -> 4857.4
B12: 45709 | C12: Macbook M4 with Airpods 4 NC 7 Units $2349 WB Card | D12: 7 | E12: 2349 | F12: =E12*D12 -> 16443 | G12: =F12/11 -> 1494.8182 | M12: =L12*K12 -> 0 | N12: =M12*13.04/100 -> 0
B13: 45709 | C13: Macbook M4 with Airpods 4 NC 1 Unit $2349 ARB Card | D13: 1 | E13: 2349 | F13: =E13*D13 -> 2349 | G13: =F13/11 -> 213.54545 | I13: 45705 | J13: Google Chrome Cast 250Units $149 WB | K13: 250 | L13: 149 | M13: =L13*K13 -> 37250 | N13: =M13*13.04/100 -> 4857.4
B14: 45709 | C14: Macbook M4 with Airpods 4 NC 1 Unit $ 2349 (apple Hornsby Pending collection) WB Card | D14: 1 | E14: 2349 | F14: =E14*D14 -> 2349 | G14: =F14/11 -> 213.54545 | M14: =L14*K14 -> 0 | N14: =M14*13.04/100 -> 0
B15: 45709 | C15: Instax wide 400 10 Units $ 188 (Harvey Norman Castle Hills Pending collection) | D15: 10 | E15: 188 | F15: =E15*D15 -> 1880 | G15: =F15/11 -> 170.90909 | I15: 45706 | J15: Starlink V4 200Units $549 WB | K15: 200 | L15: 549 | M15: =L15*K15 -> 109800 | N15: =M15*13.04/100 -> 14317.92
B16: 45709 | C16: Innstax mini Evo 1 unit $248 HN CH | D16: 1 | E16: 248 | F16: =E16*D16 -> 248 | G16: =F16/11 -> 22.545455 | I16: 45706 | J16: JBL Charge.5 6Units $145 WB | K16: 6 | L16: 145 | M16: =L16*K16 -> 870 | N16: =M16*13.04/100 -> 113.448
B17: 45709 | C17: Instax Li Play 1 Unit $203 HN CH | D17: 1 | E17: 203 | F17: =E17*D17 -> 203 | G17: =F17/11 -> 18.454545 | I17: 45706 | J17: PS5 15Units $695 ARB | K17: 15 | L17: 695 | M17: =L17*K17 -> 10425 | N17: =M17*13.04/100 -> 1359.42
B18: 45709 | C18: Instax mini 40 1 unit $143 HN CH | D18: 1 | E18: 143 | F18: =E18*D18 -> 143 | G18: =F18/11 -> 13 | M18: =L18*K18 -> 0 | N18: =M18*13.04/100 -> 0
B19: 45709 | C19: Instax mini 99 Bundle 1 unit $250 JBHIFI CH | D19: 1 | E19: 250 | F19: =E19*D19 -> 250 | G19: =F19/11 -> 22.727273 | I19: 45727 | J19: Starlink V4 ($80,000 Paid) | K19: 153 | L19: 520 | M19: =L19*K19 -> 79560 | N19: =M19*13.04/100 -> 10374.624
F20: =E20*D20 -> 0 | G20: =F20/11 -> 0 | I20: 45727 | J20: Google streamer (In System Google Chrome Cast) ($37,500 Paid) | K20: 250 | L20: 149 | M20: =L20*K20 -> 37250 | N20: =M20*13.04/100 -> 4857.4
F21: =E21*D21 -> 0 | G21: =F21/11 -> 0 | M21: =L21*K21 -> 0 | N21: =M21*13.04/100 -> 0
F22: =E22*D22 -> 0 | G22: =F22/11 -> 0 | I22: 45750 | J22: 10 PS5 Purchased in NZ $759 | K22: 10 | L22: 759 | M22: =L22*K22 -> 7590 | N22: =M22*13.04/100 -> 989.736
B23: 45710 | C23: Mac Book 4 Anwar Ali | D23: 3 | E23: 2364 | F23: =E23*D23 -> 7092 | G23: =F23/11 -> 644.72727 | M23: =L23*K23 -> 0 | N23: =M23*13.04/100 -> 0
B24: 45710 | C24: Mac Book 4 Noaman Mughal | D24: 10 | E24: 2349 | F24: =E24*D24 -> 23490 | G24: =F24/11 -> 2135.4545 | I24: 45784 | J24: Starlink V4 Noel Leeming | K24: 147 | L24: 520 | M24: =L24*K24 -> 76440 | N24: =M24*13.04/100 -> 9967.776
B25: 45711 | C25: Mac Book 4 Waheed NAB CR Card | D25: 1 | E25: 2349 | F25: =E25*D25 -> 2349 | G25: =F25/11 -> 213.54545 | I25: 45784 | J25: Instax Flim 20 pack Noel Leeming | K25: 500 | L25: 28.99 | M25: =L25*K25 -> 14495 | N25: =M25*13.04/100 -> 1890.148
B26: 45711 | C26: Mac Book 4 Waheed NAB CR Card | D26: 1 | E26: 2349 | F26: =E26*D26 -> 2349 | I26: 45784 | J26: Instax Mini Evo Noel Leeming | K26: 200 | L26: 328.99 | M26: =L26*K26 -> 65798 | N26: =M26*13.04/100 -> 8580.0592
B27: 45711 | C27: IMac4 Waheed NAB CR Card | D27: 1 | E27: 1919 | F27: =E27*D27 -> 1919 | G27: =F27/11 -> 174.45455 | I27: 45784 | J27: PS5 Astrobot Noel Leeming | K27: 10 | L27: 759 | M27: =L27*K27 -> 7590 | N27: =M27*13.04/100 -> 989.736
F28: =E28*D28 -> 0 | G28: =F28/11 -> 0 | I28: 45784 | J28: PS5 Astrobot Noel Leeming | K28: 10 | L28: 759 | M28: =L28*K28 -> 7590 | N28: =M28*13.04/100 -> 989.736
B29: 45714 | C29: Mac Book 4 AMGT Cards | D29: 4 | E29: 2349 | F29: =E29*D29 -> 9396 | G29: =F29/11 -> 854.18182 | I29: 45784 | J29: PS5 Astrobot Noel Leeming | K29: 2 | L29: 759 | M29: =L29*K29 -> 1518 | N29: =M29*13.04/100 -> 197.9472
B30: 45714 | C30: Mac Book 4 Waheed Card | D30: 3 | E30: 2349 | F30: =E30*D30 -> 7047 | G30: =F30/11 -> 640.63636 | I30: 45784 | J30: PS5 Astrobot Noel Leeming | K30: 2 | L30: 759 | M30: =L30*K30 -> 1518 | N30: =M30*13.04/100 -> 197.9472
F31: =E31*D31 -> 0 | G31: =F31/11 -> 0 | I31: 45784 | J31: PS5 Astrobot Noel Leeming | K31: 10 | L31: 759 | M31: =L31*K31 -> 7590 | N31: =M31*13.04/100 -> 989.736
B32: 45715 | C32: Mac Book 4 AMGT Cards | D32: 3 | E32: 2349 | F32: =E32*D32 -> 7047 | G32: =F32/11 -> 640.63636 | I32: 45784 | J32: Google Tv Streamer Noel Leeming | K32: 250 | L32: 149 | M32: =L32*K32 -> 37250 | N32: =M32*13.04/100 -> 4857.4
B33: 45715 | C33: Mac Book 4 Waheed Card | D33: 10 | E33: 2349 | F33: =E33*D33 -> 23490 | G33: =F33/11 -> 2135.4545 | I33: 45784 | J33: Instax Flim 20 pack Noel Leeming | K33: 200 | L33: 28.99 | M33: =L33*K33 -> 5798 | N33: =M33*13.04/100 -> 756.0592
F34: =E34*D34 -> 0 | G34: =F34/11 -> 0 | M34: =L34*K34 -> 0 | N34: =M34*13.04/100 -> 0
F35: =E35*D35 -> 0 | G35: =F35/11 -> 0 | M35: =L35*K35 -> 0 | N35: =M35*13.04/100 -> 0
B36: 45718 | C36: Mac Book Pro 14 inc M4 (Waheed GC) | D36: 1 | E36: 2349 | F36: =E36*D36 -> 2349 | G36: =F36/11 -> 213.54545 | I36: 45785 | J36: Canon Camera Noel Leeming | K36: 5 | L36: 755 | M36: =L36*K36 -> 3775 | N36: =M36*13.04/100 -> 492.26
B37: 45718 | C37: Mac Book Pro 14 inc M4 (Waheed GC) | D37: 1 | E37: 2364 | F37: =E37*D37 -> 2364 | G37: =F37/11 -> 214.90909 | I37: 45785 | J37: Osmo Pocket 3 Noel Leeming | K37: 5 | L37: 965 | M37: =L37*K37 -> 4825 | N37: =M37*13.04/100 -> 629.18
B38: 45719 | C38: Mac Book Pro 14 inc M4 (Waheed GC) | D38: 1 | E38: 2349 | F38: =E38*D38 -> 2349 | G38: =F38/11 -> 213.54545 | I38: 45785 | J38: Osmo Pocket 3 Creator Combo Noel Leeming | K38: 5 | L38: 1205 | M38: =L38*K38 -> 6025 | N38: =M38*13.04/100 -> 785.66
B39: 45719 | C39: Mac Book Pro 14 inc M4 (Waheed GC) | D39: 1 | E39: 2364 | F39: =E39*D39 -> 2364 | G39: =F39/11 -> 214.90909 | M39: =L39*K39 -> 0 | N39: =M39*13.04/100 -> 0
B40: 45720 | C40: Mac Book Pro 14 inc M4 (Waheed GC) | D40: 2 | E40: 2349 | F40: =E40*D40 -> 4698 | G40: =F40/11 -> 427.09091 | M40: =L40*K40 -> 0 | N40: =M40*13.04/100 -> 0
B41: 45720 | C41: Mac Book Pro 14 inc M4 (Waheed GC) | D41: 1 | E41: 2364 | F41: =E41*D41 -> 2364 | G41: =F41/11 -> 214.90909 | I41: 45805 | J41: Starlink V4 200 * $492 | K41: 200 | L41: 492 | M41: =L41*K41 -> 98400 | N41: =M41*13.04/100 -> 12831.36
...

Sheet Pending_Stock
B2: Australia | H2: Newzeland
B3: Purchase Date | C3: Product Name | D3: Qty (Total) | E3: Qty Received | F3: Qty Pending | H3: Purchase Date | I3: Product Name | J3: Qty (Total) | K3: Qty Received | L3: Qty Pending
B4: 45617 | C4: STARLINK MINI | D4: 1 | E4: 1 | F4: =D4-E4 -> 0 | H4: 45695 | I4: JBL CHARGE 5 | J4: 17 | K4: 17 | L4: =J4-K4 -> 0
B5: 45612 | C5: JBL CHARGE 5 | D5: 3 | E5: 3 | F5: =D5-E5 -> 0 | H5: 500 stock | I5: STARLINK MINI | J5: 100 | K5: 100 | L5: =J5-K5 -> 0
B6: 45644 | C6: JBL CHARGE 5 | D6: 32 | E6: 32 | F6: =D6-E6 -> 0 | L6: =J6-K6 -> 0 | N6: Formula for fetching Pending products quantity name wise from Australia table
B7: 45652 | C7: JBL CHARGE 5 | D7: 40 | E7: 40 | F7: =D7-E7 -> 0 | H7: 45831 | I7: CANON SX740 | J7: 4 | K7: 4 | L7: =J7-K7 -> 0 | N7: "=SUMIF(Pending_Stock!C:C, A2, Pending_Stock!F:F)"
B8: 45652 | C8: JBL CHARGE 5 | D8: 75 | E8: 75 | F8: =D8-E8 -> 0 | L8: =J8-K8 -> 0
B9: 45652 | C9: ESSENTIAL FLIP | D9: 10 | E9: 10 | F9: =D9-E9 -> 0 | H9: 45870 | I9: CANON G7X Mark III | J9: 10 | K9: 10 | L9: =J9-K9 -> 0
B10: 45652 | C10: MACBOOK M4 | D10: 1 | E10: 1 | F10: =D10-E10 -> 0 | H10: 45870 | I10: CANON G7X Mark III | J10: 5 | K10: 5 | L10: =J10-K10 -> 0 | N10: Formula for fetching Pending products quantity name wise from Newzeland table
B11: 45652 | C11: STARLINK HIGH.P KIT | D11: 11 | E11: 11 | F11: =D11-E11 -> 0 | H11: 45870 | I11: CANON LENSE | J11: 2 | K11: 2 | L11: =J11-K11 -> 0 | N11: =SUMIF(Pending_Stock!I:I, A3, Pending_Stock!L:L)'
F12: =D12-E12 -> 0 | H12: 45870 | I12: CANON G7X Mark III | J12: 1 | K12: 1 | L12: =J12-K12 -> 0
B13: 45709 | C13: MACBOOK M4 | D13: 1 | E13: 1 | F13: =D13-E13 -> 0 | H13: 45870 | I13: CANON SX740 | J13: 20 | K13: 20 | L13: =J13-K13 -> 0
B14: 45709 | C14: AIRPODS | D14: 1 | E14: 1 | F14: =D14-E14 -> 0 | H14: 45870 | I14: CANON G7X Mark III | J14: 1 | K14: 1 | L14: =J14-K14 -> 0
B15: 45709 | C15: INSTAX WIDE 400 | D15: 10 | E15: 10 | F15: =D15-E15 -> 0 | L15: =J15-K15 -> 0
F16: =D16-E16 -> 0 | H16: 45864 | I16: CANON SX740 | J16: 10 | K16: 10 | L16: =J16-K16 -> 0
B17: 45730 | C17: PS5 | D17: 5 | E17: 5 | F17: =D17-E17 -> 0 | H17: 45864 | I17: CANON SX740 | J17: 10 | K17: 10 | L17: =J17-K17 -> 0
B18: 45730 | C18: INSTAX MINI 99 BUNDEL | D18: 8 | E18: 8 | F18: =D18-E18 -> 0 | L18: =J18-K18 -> 0
F19: =D19-E19 -> 0 | H19: 45880 | I19: INSTAX MINI EVO | J19: 50 | K19: 50 | L19: =J19-K19 -> 0
B20: 45733 | C20: INSTAX MINI 99 BUNDEL | D20: 3 | E20: 3 | F20: =D20-E20 -> 0 | L20: =J20-K20 -> 0
F21: =D21-E21 -> 0 | H21: 45889 | I21: CANON SX740 | J21: 0 | L21: =J21-K21 -> 0 | M21: double purchase
B22: 45739 | C22: Macbook Air 24/512 GB | D22: 1 | E22: 1 | F22: =D22-E22 -> 0 | H22: 45889 | I22: CANON SX740 | J22: 0 | L22: =J22-K22 -> 0 | M22: double purchase
B23: 45739 | C23: Macbook Air 24/512 GB | D23: 2 | E23: 2 | F23: =D23-E23 -> 0 | H23: 45889 | I23: CANON SX740 | J23: 1 | K23: 1 | L23: =J23-K23 -> 0
B24: 45740 | C24: Macbook Air 24/512 GB | D24: 2 | E24: 2 | F24: =D24-E24 -> 0 | H24: 45889 | I24: CANON SX740 | J24: 4 | K24: 4 | L24: =J24-K24 -> 0
B25: 45740 | C25: Macbook Air 24/512 GB | D25: 2 | E25: 2 | F25: =D25-E25 -> 0 | H25: 45895 | I25: INSTAX MINI EVO | J25: 50 | K25: 50 | L25: =J25-K25 -> 0
F26: =D26-E26 -> 0 | H26: 45895 | I26: INSTAX MINI EVO | J26: 50 | K26: 50 | L26: =J26-K26 -> 0
B27: 45742 | C27: Macbook Air 24/512 GB | D27: 10 | E27: 10 | F27: =D27-E27 -> 0 | H27: 45957 | I27: CANON G7X Mark III | J27: 1 | K27: 1 | L27: =J27-K27 -> 0
B28: 45742 | C28: PS5 | D28: 2 | E28: 2 | F28: =D28-E28 -> 0 | H28: 45957 | I28: CANON G7X Mark III | J28: 2 | K28: 2 | L28: =J28-K28 -> 0
F29: =D29-E29 -> 0 | H29: 45958 | I29: CANON G7X Mark III | J29: 10 | K29: 10 | L29: =J29-K29 -> 0
B30: 45743 | C30: Macbook Air 24/512 GB | D30: 10 | E30: 10 | F30: =D30-E30 -> 0 | H30: 45958 | I30: CANON SX740 | J30: 3 | K30: 3 | L30: =J30-K30 -> 0
B31: 45743 | C31: Macbook Pro 16/512 | D31: 2 | E31: 2 | F31: =D31-E31 -> 0 | H31: 45958 | I31: CANON G7X Mark III | J31: 6 | K31: 6 | L31: =J31-K31 -> 0
F32: =D32-E32 -> 0 | H32: 45958 | I32: CANON G7X Mark III | J32: 1 | K32: 1 | L32: =J32-K32 -> 0
B33: 45744 | C33: Macbook Air 24/512 GB | D33: 2 | E33: 2 | F33: =D33-E33 -> 0 | H33: 45990 | I33: CANON G7X Mark III | J33: 1 | K33: 1 | L33: =J33-K33 -> 0
B34: 45744 | C34: Macbook Pro 16/512 | D34: 1 | E34: 1 | F34: =D34-E34 -> 0 | H34: 45990 | I34: CANON G7X Mark III | J34: 1 | K34: 1 | L34: =J34-K34 -> 0
B35: 45744 | C35: INSTAX MINI EVO | D35: 4 | E35: 4 | F35: =D35-E35 -> 0 | H35: 45990 | I35: CANON G7X Mark III | J35: 3 | K35: 3 | L35: =J35-K35 -> 0
B36: 45744 | C36: INSTAX MINI 12 | D36: 3 | E36: 3 | F36: =D36-E36 -> 0 | H36: 45990 | I36: CANON G7X Mark III | J36: 10 | K36: 10 | L36: =J36-K36 -> 0
F37: =D37-E37 -> 0 | H37: 45990 | I37: CANON G7X Mark III | J37: 12 | K37: 12 | L37: =J37-K37 -> 0
B38: 45745 | C38: Macbook Air 24/512 GB | D38: 2 | E38: 2 | F38: =D38-E38 -> 0 | H38: 45966 | I38: CANON G7X Mark III | J38: 10 | K38: 10 | L38: =J38-K38 -> 0
B39: 45745 | C39: Macbook Pro 16/512 | D39: 2 | E39: 2 | F39: =D39-E39 -> 0 | H39: 45966 | I39: CANON G7X Mark III | J39: 1 | K39: 1 | L39: =J39-K39 -> 0
B40: 45745 | C40: PS5 | D40: 1 | E40: 1 | F40: =D40-E40 -> 0 | H40: 45966 | I40: CANON SX740 | J40: 3 | K40: 3 | L40: =J40-K40 -> 0
B41: 45749 | C41: Macbook Pro 16/1TB | D41: 4 | E41: 4 | F41: =D41-E41 -> 0 | H41: 45966 | I41: CANON G7X Mark III | J41: 2 | K41: 2 | L41: =J41-K41 -> 0
...

Sheet ShipToDubai
C3: Shipping To Dubai
B4: Shipping Date | C4: Product Name | D4: Qty Shipped | E4: Status | F4: Qty Received | G4: Qty Remaining
B5: 20/02/2025 | C5: STARLINK V4 | D5: 201 | E5: Opening | F5: 201 | G5: =D5-F5 -> 0 | K5: HOLD STOCK AMGT
B6: 20/02/2025 | C6: STARLINK MINI | D6: 200 | E6: Opening | F6: 200 | G6: =D6-F6 -> 0 | K6: Product Name | L6: Qty
B7: 20/02/2025 | C7: JBL CHARGE 5 | D7: 17 | E7: Opening | F7: 17 | G7: =D7-F7 -> 0 | K7: PRINTER | L7: 1
B8: 20/02/2025 | C8: CHROME CAST | D8: 309 | E8: Opening | F8: 309 | G8: =D8-F8 -> 0
B9: 20/02/2025 | C9: PS5 | D9: 15 | E9: Opening | F9: 15 | G9: =D9-F9 -> 0 | K9: MACBOOK M3 | L9: 2
B10: 20/02/2025 | C10: BREVILLE COFFEE MACHINE | D10: 2 | E10: Opening | F10: 2 | G10: =D10-F10 -> 0 | K10: COFFEE MACHINE | L10: 1
B11: 20/02/2025 | C11: DELONGI COFFEE MACHINE | D11: 2 | E11: Opening | F11: 2 | G11: =D11-F11 -> 0 | K11: DYSON | L11: 2
B12: 20/02/2025 | C12: APPLE I MAC | D12: 5 | E12: Opening | F12: 5 | G12: =D12-F12 -> 0
B13: 20/02/2025 | C13: DYSON | D13: 2 | E13: Opening | F13: 2 | G13: =D13-F13 -> 0
B14: 20/02/2025 | C14: MACBOOK M3 | D14: 2 | E14: Opening | F14: 2 | G14: =D14-F14 -> 0
B15: 20/02/2025 | C15: STARLINK HIGH.P KIT | D15: 10 | E15: Opening | F15: 10 | G15: =D15-F15 -> 0
B16: 20/02/2025 | C16: APPLE WATCH ULTRA | D16: 1 | E16: Opening | F16: 1 | G16: =D16-F16 -> 0
B17: 20/02/2025 | C17: PRINTER | D17: 1 | E17: Opening | F17: 1 | G17: =D17-F17 -> 0
B18: 20/02/2025 | C18: DJI MAVIC PRO 3 DRONE | D18: 2 | E18: Opening | F18: 2 | G18: =D18-F18 -> 0
G19: =D19-F19 -> 0
B20: 45711 | C20: MACBOOK M4 | D20: 23 | E20: Received | F20: 23 | G20: =D20-F20 -> 0
B21: 45711 | C21: JBL CHARGE 5 | D21: 188 | E21: Received | F21: 188 | G21: =D21-F21 -> 0
B22: 45711 | C22: APPLE I MAC | D22: 2 | E22: Received | F22: 2 | G22: =D22-F22 -> 0
B23: 45711 | C23: AIRPODS | D23: 21 | E23: Received | F23: 21 | G23: =D23-F23 -> 0
B24: 45711 | C24: INSTAX WIDE 400 | D24: 5 | E24: Received | F24: 5 | G24: =D24-F24 -> 0
B25: 45711 | C25: INSTAX MINI EVO | D25: 1 | E25: Received | F25: 1 | G25: =D25-F25 -> 0
B26: 45711 | C26: INSTAX Li PLAY | D26: 1 | E26: Received | F26: 1 | G26: =D26-F26 -> 0
B27: 45711 | C27: INSTAX MINI 40 | D27: 1 | E27: Received | F27: 1 | G27: =D27-F27 -> 0
B28: 45711 | C28: INSTAX MINI 99 | D28: 1 | E28: Received | F28: 1 | G28: =D28-F28 -> 0
G29: =D29-F29 -> 0
B30: 45719 | C30: Meta Quest 3 512 | D30: 13 | E30: Purchased in Dubai | F30: 13 | G30: =D30-F30 -> 0
B31: 45719 | C31: iPhone16 Pro Max 256 | D31: 20 | E31: Purchased in Dubai | F31: 20 | G31: =D31-F31 -> 0
B32: 45719 | C32: iPad Pro 11 256 Cellular Unlock | D32: 4 | E32: Purchased in Dubai | F32: 4 | G32: =D32-F32 -> 0
B33: 45719 | C33: AIRPODS | D33: 4 | E33: Purchased in Dubai | F33: 4 | G33: =D33-F33 -> 0
B34: 45719 | C34: iPad Pro 11 256 Wifi Only | D34: 14 | E34: Purchased in Dubai | F34: 14 | G34: =D34-F34 -> 0
B35: 45719 | C35: iPad Air 13 128 Wifi Only | D35: 2 | E35: Purchased in Dubai | F35: 2 | G35: =D35-F35 -> 0
B36: 45719 | C36: iPad Air 13 256 Wifi Only | D36: 1 | E36: Purchased in Dubai | F36: 1 | G36: =D36-F36 -> 0
G37: =D37-F37 -> 0
B38: 45728 | C38: iPhone16 Pro 256 | D38: 2 | E38: Cell Wear Usa Purchase | F38: 2 | G38: =D38-F38 -> 0
B39: 45728 | C39: iPhone16 Pro 128 | D39: 1 | E39: Cell Wear Usa Purchase | F39: 1 | G39: =D39-F39 -> 0
B40: 45728 | C40: Meta Quest 3 512 | D40: 2 | E40: Cell Wear Usa Purchase | F40: 2 | G40: =D40-F40 -> 0
B41: 45728 | C41: Ps5 Controller Dual sense | D41: 12 | E41: Cell Wear Usa Purchase | F41: 12 | G41: =D41-F41 -> 0
B42: 45728 | C42: Beats Fit Pro | D42: 17 | E42: Cell Wear Usa Purchase | F42: 17 | G42: =D42-F42 -> 0
...

Sheet Monthly Sales
A1: {=A1:K74} -> 0
B2: Date | C2: Product Name | D2: Qty | E2: Per Unit Sale | F2: Per unit Purchase | G2: Per Unit Profit | H2: Total Sale | I2: Total Purhcase | J2: Total Profit
B3: 45718 | C3: STARLINK MINI | D3: 5 | E3: 1180 | F3: 1199.7871 | G3: =E3-F3 -> -19.78712 | H3: =E3*D3 -> 5900 | I3: =F3*D3 -> 5998.9356 | J3: =H3-I3 -> -98.9356
B4: 45722 | C4: MACBOOK M4 | D4: 20 | E4: 4900 | F4: 5019.6 | G4: =E4-F4 -> -119.6 | H4: =E4*D4 -> 98000 | I4: =F4*D4 -> 100392 | J4: =H4-I4 -> -2392
B5: 45722 | C5: STARLINK MINI | D5: 50 | E5: 1140 | F5: 1199.7871 | G5: =E5-F5 -> -59.78712 | H5: =E5*D5 -> 57000 | I5: =F5*D5 -> 59989.356 | J5: =H5-I5 -> -2989.356
B6: 45723 | C6: STARLINK MINI | D6: 44 | E6: 1135 | F6: 1199.7871 | G6: =E6-F6 -> -64.78712 | H6: =E6*D6 -> 49940 | I6: =F6*D6 -> 52790.633 | J6: =H6-I6 -> -2850.6333
B7: 45728 | C7: STARLINK MINI | D7: 2 | E7: 1135 | F7: 1199.7871 | G7: =E7-F7 -> -64.78712 | H7: =E7*D7 -> 2270 | I7: =F7*D7 -> 2399.5742 | J7: =H7-I7 -> -129.57424
B8: 45729 | C8: STARLINK MINI | D8: 30 | E8: 1125 | F8: 1199.7871 | G8: =E8-F8 -> -74.78712 | H8: =E8*D8 -> 33750 | I8: =F8*D8 -> 35993.614 | J8: =H8-I8 -> -2243.6136
B9: 45729 | C9: APPLE WATCH ULTRA | D9: 1 | E9: 2150 | F9: 2250 | G9: =E9-F9 -> -100 | H9: =E9*D9 -> 2150 | I9: =F9*D9 -> 2250 | J9: =H9-I9 -> -100
B10: 45733 | C10: MACBOOK M4 | D10: 2 | E10: 4930 | F10: 5019.6 | G10: =E10-F10 -> -89.6 | H10: =E10*D10 -> 9860 | I10: =F10*D10 -> 10039.2 | J10: =H10-I10 -> -179.2
B11: 45734 | C11: MACBOOK M4 | D11: 31 | E11: 4900 | F11: 5019.6 | G11: =E11-F11 -> -119.6 | H11: =E11*D11 -> 151900 | I11: =F11*D11 -> 155607.6 | J11: =H11-I11 -> -3707.6
B12: 45734 | C12: STARLINK MINI | D12: 3 | E12: 1115 | F12: 1199.7871 | G12: =E12-F12 -> -84.78712 | H12: =E12*D12 -> 3345 | I12: =F12*D12 -> 3599.3614 | J12: =H12-I12 -> -254.36136
B13: 45738 | C13: STARLINK MINI | D13: 4 | E13: 1120 | F13: 1199.7871 | G13: =E13-F13 -> -79.78712 | H13: =E13*D13 -> 4480 | I13: =F13*D13 -> 4799.1485 | J13: =H13-I13 -> -319.14848
B14: 45742 | C14: MACBOOK M4 | D14: 2 | E14: 4890 | F14: 5019.6 | G14: =E14-F14 -> -129.6 | H14: =E14*D14 -> 9780 | I14: =F14*D14 -> 10039.2 | J14: =H14-I14 -> -259.2
... B19: 45744 | C19: MACBOOK M4 | D19: 2 | E19: 4870 | F19: 5019.6 | G19: =E19-F19 -> -149.6 | H19: =E19*D19 -> 9740 | I19: =F19*D19 -> 10039.2 | J19: =H19-I19 -> -299.2
I20: Total Loss | J20: =SUM(J3:J19) -> -33070.257
B21: Date | C21: Product Name | D21: Qty | E21: Per Unit Sale | F21: Per unit Purchase | G21: Per Unit Profit | H21: Total Sale | I21: Total Purhcase | J21: Total Profit
